2021-09-27 20:53:21,245 ERROR: Exception on /reset_password_request [POST] [in E:\Repos\personal\Flask Mega Tutorial\venv\lib\site-packages\flask\app.py:1454]
Traceback (most recent call last):
  File "E:\Repos\personal\Flask Mega Tutorial\venv\lib\site-packages\flask\app.py", line 2070, in wsgi_app
    response = self.full_dispatch_request()
  File "E:\Repos\personal\Flask Mega Tutorial\venv\lib\site-packages\flask\app.py", line 1515, in full_dispatch_request
    rv = self.handle_user_exception(e)
  File "E:\Repos\personal\Flask Mega Tutorial\venv\lib\site-packages\flask\app.py", line 1513, in full_dispatch_request
    rv = self.dispatch_request()
  File "E:\Repos\personal\Flask Mega Tutorial\venv\lib\site-packages\flask\app.py", line 1499, in dispatch_request
    return self.ensure_sync(self.view_functions[rule.endpoint])(**req.view_args)
  File "E:\Repos\personal\Flask Mega Tutorial\microblog\app\routes.py", line 160, in reset_password_request
    send_password_reset_email(user)
  File "E:\Repos\personal\Flask Mega Tutorial\microblog\app\email.py", line 12, in send_password_reset_email
    token = user.get_reset_password_token()
  File "E:\Repos\personal\Flask Mega Tutorial\microblog\app\models.py", line 55, in get_reset_password_token
    return jwt.encode({'reset_password': self.id, 'exp': time() + expires_in},
AttributeError: 'str' object has no attribute 'decode'
2021-09-27 20:53:27,294 ERROR: Exception on /reset_password_request [POST] [in E:\Repos\personal\Flask Mega Tutorial\venv\lib\site-packages\flask\app.py:1454]
Traceback (most recent call last):
  File "E:\Repos\personal\Flask Mega Tutorial\venv\lib\site-packages\flask\app.py", line 2070, in wsgi_app
    response = self.full_dispatch_request()
  File "E:\Repos\personal\Flask Mega Tutorial\venv\lib\site-packages\flask\app.py", line 1515, in full_dispatch_request
    rv = self.handle_user_exception(e)
  File "E:\Repos\personal\Flask Mega Tutorial\venv\lib\site-packages\flask\app.py", line 1513, in full_dispatch_request
    rv = self.dispatch_request()
  File "E:\Repos\personal\Flask Mega Tutorial\venv\lib\site-packages\flask\app.py", line 1499, in dispatch_request
    return self.ensure_sync(self.view_functions[rule.endpoint])(**req.view_args)
  File "E:\Repos\personal\Flask Mega Tutorial\microblog\app\routes.py", line 160, in reset_password_request
    send_password_reset_email(user)
  File "E:\Repos\personal\Flask Mega Tutorial\microblog\app\email.py", line 12, in send_password_reset_email
    token = user.get_reset_password_token()
  File "E:\Repos\personal\Flask Mega Tutorial\microblog\app\models.py", line 55, in get_reset_password_token
    return jwt.encode({'reset_password': self.id, 'exp': time() + expires_in},
AttributeError: 'str' object has no attribute 'decode'
2021-09-27 20:53:56,964 INFO: Microblog startup [in E:\Repos\personal\Flask Mega Tutorial\microblog\app\__init__.py:41]
2021-09-27 21:24:51,974 INFO: Microblog startup [in E:\Repos\personal\Flask Mega Tutorial\microblog\app\__init__.py:43]
2021-09-27 21:25:41,909 INFO: Microblog startup [in E:\Repos\personal\Flask Mega Tutorial\microblog\app\__init__.py:43]
2021-09-27 21:26:12,113 INFO: Microblog startup [in E:\Repos\personal\Flask Mega Tutorial\microblog\app\__init__.py:43]
2021-09-27 21:26:32,613 INFO: Microblog startup [in E:\Repos\personal\Flask Mega Tutorial\microblog\app\__init__.py:43]
2021-09-27 21:59:57,721 INFO: Microblog startup [in E:\Repos\personal\Flask Mega Tutorial\microblog\app\__init__.py:45]
2021-09-27 22:00:01,421 ERROR: Exception on /login [GET] [in E:\Repos\personal\Flask Mega Tutorial\venv\lib\site-packages\flask\app.py:1454]
Traceback (most recent call last):
  File "E:\Repos\personal\Flask Mega Tutorial\venv\lib\site-packages\flask\app.py", line 2070, in wsgi_app
    response = self.full_dispatch_request()
  File "E:\Repos\personal\Flask Mega Tutorial\venv\lib\site-packages\flask\app.py", line 1515, in full_dispatch_request
    rv = self.handle_user_exception(e)
  File "E:\Repos\personal\Flask Mega Tutorial\venv\lib\site-packages\flask\app.py", line 1513, in full_dispatch_request
    rv = self.dispatch_request()
  File "E:\Repos\personal\Flask Mega Tutorial\venv\lib\site-packages\flask\app.py", line 1499, in dispatch_request
    return self.ensure_sync(self.view_functions[rule.endpoint])(**req.view_args)
  File "E:\Repos\personal\Flask Mega Tutorial\microblog\app\routes.py", line 45, in login
    return render_template('login.html', title='Sign In', form=form)
  File "E:\Repos\personal\Flask Mega Tutorial\venv\lib\site-packages\flask\templating.py", line 147, in render_template
    return _render(
  File "E:\Repos\personal\Flask Mega Tutorial\venv\lib\site-packages\flask\templating.py", line 128, in _render
    rv = template.render(context)
  File "E:\Repos\personal\Flask Mega Tutorial\venv\lib\site-packages\jinja2\environment.py", line 1304, in render
    self.environment.handle_exception()
  File "E:\Repos\personal\Flask Mega Tutorial\venv\lib\site-packages\jinja2\environment.py", line 925, in handle_exception
    raise rewrite_traceback_stack(source=source)
  File "E:\Repos\personal\Flask Mega Tutorial\microblog\app\templates\login.html", line 1, in top-level template code
    {% extends "base.html" %}
  File "E:\Repos\personal\Flask Mega Tutorial\venv\lib\site-packages\jinja2\environment.py", line 925, in handle_exception
    raise rewrite_traceback_stack(source=source)
  File "E:\Repos\personal\Flask Mega Tutorial\microblog\app\templates\base.html", line 6, in template
    {{% endblock %}}
jinja2.exceptions.TemplateSyntaxError: unexpected '%'
2021-09-27 22:00:01,882 ERROR: Exception on /favicon.ico [GET] [in E:\Repos\personal\Flask Mega Tutorial\venv\lib\site-packages\flask\app.py:1454]
Traceback (most recent call last):
  File "E:\Repos\personal\Flask Mega Tutorial\venv\lib\site-packages\flask\app.py", line 1513, in full_dispatch_request
    rv = self.dispatch_request()
  File "E:\Repos\personal\Flask Mega Tutorial\venv\lib\site-packages\flask\app.py", line 1489, in dispatch_request
    self.raise_routing_exception(req)
  File "E:\Repos\personal\Flask Mega Tutorial\venv\lib\site-packages\flask\app.py", line 1471, in raise_routing_exception
    raise request.routing_exception  # type: ignore
  File "E:\Repos\personal\Flask Mega Tutorial\venv\lib\site-packages\flask\ctx.py", line 367, in match_request
    result = self.url_adapter.match(return_rule=True)  # type: ignore
  File "E:\Repos\personal\Flask Mega Tutorial\venv\lib\site-packages\werkzeug\routing.py", line 2032, in match
    raise NotFound()
werkzeug.exceptions.NotFound: 404 Not Found: The requested URL was not found on the server. If you entered the URL manually please check your spelling and try again.

During handling of the above exception, another exception occurred:

Traceback (most recent call last):
  File "E:\Repos\personal\Flask Mega Tutorial\venv\lib\site-packages\flask\app.py", line 2070, in wsgi_app
    response = self.full_dispatch_request()
  File "E:\Repos\personal\Flask Mega Tutorial\venv\lib\site-packages\flask\app.py", line 1515, in full_dispatch_request
    rv = self.handle_user_exception(e)
  File "E:\Repos\personal\Flask Mega Tutorial\venv\lib\site-packages\flask\app.py", line 1383, in handle_user_exception
    return self.handle_http_exception(e)
  File "E:\Repos\personal\Flask Mega Tutorial\venv\lib\site-packages\flask\app.py", line 1323, in handle_http_exception
    return self.ensure_sync(handler)(e)
  File "E:\Repos\personal\Flask Mega Tutorial\microblog\app\errors.py", line 6, in not_found_error
    return render_template('404.html'), 404
  File "E:\Repos\personal\Flask Mega Tutorial\venv\lib\site-packages\flask\templating.py", line 147, in render_template
    return _render(
  File "E:\Repos\personal\Flask Mega Tutorial\venv\lib\site-packages\flask\templating.py", line 128, in _render
    rv = template.render(context)
  File "E:\Repos\personal\Flask Mega Tutorial\venv\lib\site-packages\jinja2\environment.py", line 1304, in render
    self.environment.handle_exception()
  File "E:\Repos\personal\Flask Mega Tutorial\venv\lib\site-packages\jinja2\environment.py", line 925, in handle_exception
    raise rewrite_traceback_stack(source=source)
  File "E:\Repos\personal\Flask Mega Tutorial\microblog\app\templates\404.html", line 1, in top-level template code
    {% extends "base.html" %}
  File "E:\Repos\personal\Flask Mega Tutorial\venv\lib\site-packages\jinja2\environment.py", line 925, in handle_exception
    raise rewrite_traceback_stack(source=source)
  File "E:\Repos\personal\Flask Mega Tutorial\microblog\app\templates\base.html", line 6, in template
    {{% endblock %}}
jinja2.exceptions.TemplateSyntaxError: unexpected '%'
2021-09-27 22:00:50,207 INFO: Microblog startup [in E:\Repos\personal\Flask Mega Tutorial\microblog\app\__init__.py:45]
